<mujoco model="loquro_quadruped">
  <compiler angle="radian" meshdir="assets/"/>

  <option timestep="0.001" integrator="implicitfast" iterations="80" ls_iterations="30"/>

  <visual>
    <global offwidth="1692" offheight="936"/>
    <headlight ambient="0.45 0.45 0.45" diffuse="0.75 0.75 0.75" specular="0.15 0.15 0.15"/>
  </visual>

  <asset>
    <texture type="skybox" colorspace="auto" builtin="gradient" rgb1="0.95 0.97 1" rgb2="0.65 0.78 0.92" width="256" height="1536"/>
    <material name="ground_mat" rgba="0.84 0.87 0.82 1"/>
    
    <!-- Mallas Comunes -->
    <mesh name="cad_servo20kg_p4_correct_mesh" file="cad_servo20kg_p4_correct.stl" scale="0.001 0.001 0.001"/>
    <mesh name="servo_sin_cabezal_mesh" file="servo_sin_cabezal.stl" scale="0.001 0.001 0.001"/>
    <mesh name="tensor_aluminio_11_60_correct_mesh" file="tensor_aluminio_11_60_correct.stl" scale="0.001 0.001 0.001"/>
    <mesh name="union_servo_correct_mesh" file="union_servo_correct.stl" scale="0.001 0.001 0.001"/>

    <!-- Mallas Izquierdas -->
    <mesh name="foot_left_mesh" file="foot_left.stl" scale="0.001 0.001 0.001"/>
    <mesh name="hombro_pierna_correct_mesh" file="hombro_pierna_correct.stl" scale="0.001 0.001 0.001"/>
    <mesh name="pieza1_pierna_left_correct_mesh" file="pieza1_pierna_left_correct.stl" scale="0.001 0.001 0.001"/>
    <mesh name="pieza2_pierna_left_correct_mesh" file="pieza2_pierna_left_correct.stl" scale="0.001 0.001 0.001"/>
    <mesh name="pieza3_pierna_felt_correct_mesh" file="pieza3_pierna_felt_correct.stl" scale="0.001 0.001 0.001"/>
    <mesh name="pieza4_pierna_left_correct_mesh" file="pieza4_pierna_left_correct.stl" scale="0.001 0.001 0.001"/>

    <!-- Mallas Derechas -->
    <mesh name="foot_right_mesh" file="foot_left_right.stl" scale="0.001 0.001 0.001"/>
    <mesh name="hombro_pierna_right_mesh" file="hombro_pierna_correct_r.stl" scale="0.001 0.001 0.001"/>
    <mesh name="pieza1_pierna_right_mesh" file="pieza1_pierna_right_correct.stl" scale="0.001 0.001 0.001"/>
    <mesh name="pieza2_pierna_right_mesh" file="pieza2_pierna_right_correct.stl" scale="0.001 0.001 0.001"/>
    <mesh name="pieza3_pierna_right_mesh" file="pieza3_pierna_right_correct.stl" scale="0.001 0.001 0.001"/>
    <mesh name="pieza4_pierna_right_mesh" file="pieza4_pierna_right_correct.stl" scale="0.001 0.001 0.001"/>
  </asset>

  <worldbody>
    <geom name="ground" size="3 3 0.1" type="plane" material="ground_mat"/>
    <light pos="0 0 2.5" dir="0 0 -1"/>
    
    <body name="base" pos="0 0 0.35">
      <freejoint name="root"/>
      <geom name="base_box" size="0.15 0.075 0.025" type="box" mass="2" rgba="0.18 0.18 0.2 1"/>

      <!-- ================= PATA DELANTERA IZQUIERDA (FL) ================= -->
      <body name="fl_mount" pos="0.08 -0.075 0">
        <body name="fl_shoulder_servo" quat="0.000563312 0.707388 0.000562864 0.706825">
          <geom type="mesh" rgba="0.18 0.21 0.25 1" mesh="servo_sin_cabezal_mesh"/>
          <body name="fl_servo_u_1" pos="0 0 0.005">
            <joint name="fl_shoulder_joint" pos="0 0 0" axis="0 0 1" range="-1.5708 1.5708" armature="0.004" damping="0.12" frictionloss="0.003"/>
            <geom type="mesh" rgba="0.94 0.55 0.2 1" mesh="union_servo_correct_mesh"/>
            <body name="fl_hombro_pierna" pos="0 0 0.002">
              <geom type="mesh" rgba="0.15 0.55 0.78 1" mesh="hombro_pierna_correct_mesh"/>
              <body name="fl_knee_servo" pos="-0.02 0.023 0.02" quat="0.707388 -0.706825 0 0">
                <geom type="mesh" rgba="0.3 0.33 0.38 1" mesh="servo_sin_cabezal_mesh"/>
                <body name="fl_servo_u_2" pos="0 0 0.005" quat="0.707388 0 0 0.706825">
                  <joint name="fl_knee_joint" pos="0 0 0" axis="0 0 1" range="0 1.5708" armature="0.004" damping="0.12" frictionloss="0.003"/>
                  <geom type="mesh" rgba="0.86 0.24 0.24 1" mesh="cad_servo20kg_p4_correct_mesh"/>
                  <body name="fl_pieza1_pierna" pos="-0.02 -0.044 0.001" quat="0.374814 0 0 -0.9271">
                    <joint name="fl_pieza1_pierna_joint" pos="-0.028 0 0" axis="0 0 1" range="-1.5708 1.5708" damping="0.03" frictionloss="0.0002"/>
                    <geom type="mesh" rgba="0.96 0.82 0.18 1" mesh="pieza1_pierna_left_correct_mesh"/>
                  </body>
                </body>
              </body>
              <body name="fl_hip_servo" pos="0 0.023 0.04" quat="9.38559e-07 -9.37812e-07 0.706825 0.707388">
                <geom type="mesh" rgba="0.44 0.29 0.58 1" mesh="servo_sin_cabezal_mesh"/>
                <body name="fl_homoplato" quat="0.923879 0 0 0.382684">
                  <joint name="fl_shoulder_passive_joint" pos="0 0 0" axis="0 0 1" range="-1.5708 1.5708" damping="0.03" frictionloss="0.0002"/>
                  <geom type="mesh" rgba="0.16 0.72 0.45 1" mesh="pieza2_pierna_left_correct_mesh"/>
                  <body name="fl_tensor_aluminio" pos="0.0213 0.0211 0.0067" quat="0.707388 0 0 -0.706825">
                    <joint name="fl_tensor_aluminio_passive_joint" pos="0 0 0" axis="0 0 1" range="-1.5708 1.5708" damping="0.03" frictionloss="0.0002"/>
                    <geom type="mesh" rgba="0.7 0.72 0.7 1" mesh="tensor_aluminio_11_60_correct_mesh"/>
                  </body>
                </body>
                <body name="fl_femur" pos="0 0 0.006" quat="0.923879 0 0 0.382684">
                  <joint name="fl_femur_joint" pos="0 0 0" axis="0 0 1" range="-1.5708 1.5708" damping="0.03" frictionloss="0.0002"/>
                  <geom type="mesh" rgba="0.7 0.45 0.7 1" mesh="pieza3_pierna_felt_correct_mesh"/>
                  <body name="fl_tibia" pos="0.11 0 0.0076" quat="0.382681 0 0 -0.923881">
                    <joint name="fl_tibia_passive_joint" pos="0 0 0" axis="0 0 1" range="-1.5708 1.5708" damping="0.03" frictionloss="0.0002"/>
                    <geom type="mesh" rgba="0.24 0.65 0.65 1" mesh="pieza4_pierna_left_correct_mesh"/>
                    <geom pos="0.11 0 0.003" quat="0.707388 0 0 -0.706825" type="mesh" rgba="0.15 0.15 0.15 1" mesh="foot_left_mesh"/>
                  </body>
                </body>
              </body>
            </body>
          </body>
        </body>
      </body>

      <!-- ================= PATA DELANTERA DERECHA (FR) ================= -->
      <body name="fr_mount" pos="0.08 0.075 0">
        <body name="fr_shoulder_servo" quat="0.000563312 -0.707388 0.000562864 -0.706825">
          <geom type="mesh" rgba="0.18 0.21 0.25 1" mesh="servo_sin_cabezal_mesh"/>
          <body name="fr_servo_u_1" pos="0 0 0.005">
            <joint name="fr_shoulder_joint" pos="0 0 0" axis="0 0 1" range="-1.5708 1.5708" armature="0.004" damping="0.12" frictionloss="0.003"/>
            <geom type="mesh" rgba="0.94 0.55 0.2 1" mesh="union_servo_correct_mesh"/>
            
            <body name="fr_hombro_pierna" pos="0 0 0.002" euler="0 3.14159 3.14159">
              <geom type="mesh" rgba="0.15 0.55 0.78 1" mesh="hombro_pierna_right_mesh"/>
              
              <body name="fr_knee_servo" pos="-0.0200215 0.0230215 -0.0200215" euler="-1.571 0 3.14159">
                <geom type="mesh" rgba="0.3 0.33 0.38 1" mesh="servo_sin_cabezal_mesh"/>
                <body name="fr_servo_u_2" pos="0 0 0.005" euler="0 0 4.7">
                  <joint name="fr_knee_joint" pos="0 0 0" axis="0 0 1" range="-1.57 0" armature="0.004" damping="0.12" frictionloss="0.003"/>
                  <geom type="mesh" rgba="0.86 0.24 0.24 1" mesh="cad_servo20kg_p4_correct_mesh"/>
                  
                  <body name="fr_pieza1_pierna" pos="0.00 -0.02451 0.0093" euler="0 0 2.39">
                    <joint name="fr_pieza1_pierna_joint" pos="0 0 0" axis="0 0 1" range="-1.5708 1.5708" damping="0.03" frictionloss="0.0002"/>
                    <geom type="mesh" rgba="0.96 0.82 0.18 1" mesh="pieza1_pierna_right_mesh"/> 
                  </body>
                </body>
              </body>

              <body name="fr_hip_servo" pos="0 0.0230215 -0.04055" euler="-1.571 0 0">
                <geom type="mesh" rgba="0.44 0.29 0.58 1" mesh="servo_sin_cabezal_mesh"/>
                
                <body name="fr_homoplato" pos="0 0 0" euler="3.14159 0 -2.328">
                  <joint name="fr_shoulder_passive_joint" pos="0 0 0" axis="0 0 1" range="-1.5708 1.5708" damping="0.03" frictionloss="0.0002"/>
                  <geom type="mesh" rgba="0.16 0.72 0.45 1" mesh="pieza2_pierna_right_mesh"/> 
                  
                  <body name="fr_tensor_aluminio" pos="0.02125 0.02108 -0.006" euler=" 0 0 -1.4">
                    <joint name="fr_tensor_aluminio_passive_joint" pos="0 0 0" axis="0 0 1" range="-1.5708 1.5708" damping="0.03" frictionloss="0.0002"/>
                    <geom type="mesh" rgba="0.7 0.72 0.7 1" mesh="tensor_aluminio_11_60_correct_mesh"/>
                  </body>
                </body>

                <body name="fr_femur" pos="0 0 0.006" euler="3.14159 0 4.1">
                  <joint name="fr_femur_joint" pos="0 0 0" axis="0 0 1" range="-1.5708 1.5708" damping="0.03" frictionloss="0.0002"/>
                  <geom type="mesh" rgba="0.7 0.45 0.7 1" mesh="pieza3_pierna_right_mesh"/> 
                  
                  <body name="fr_tibia" pos="0.11 0 -0.0077" euler="0 0 -2.425">
                    <joint name="fr_tibia_passive_joint" pos="0 0 0" axis="0 0 1" range="-1.5708 1.5708" damping="0.03" frictionloss="0.0002"/>
                    <geom type="mesh" rgba="0.24 0.65 0.65 1" mesh="pieza4_pierna_right_mesh"/> 
                    
                    <geom type="mesh" rgba="0.15 0.15 0.15 1" mesh="foot_right_mesh" pos="0.11 0 -0.003" euler="0 0 -1.571"/>
                  </body>
                </body>
              </body>
            </body>
          </body>
        </body>
      </body>

      <!-- ================= PATA TRASERA IZQUIERDA (RL) ================= -->
      <body name="rl_mount" pos="-0.11 -0.075 0">
        <body name="rl_shoulder_servo" quat="0.000563312 0.707388 0.000562864 0.706825">
          <geom type="mesh" rgba="0.18 0.21 0.25 1" mesh="servo_sin_cabezal_mesh"/>
          <body name="rl_servo_u_1" pos="0 0 0.005">
            <joint name="rl_shoulder_joint" pos="0 0 0" axis="0 0 1" range="-1.5708 1.5708" armature="0.004" damping="0.12" frictionloss="0.003"/>
            <geom type="mesh" rgba="0.94 0.55 0.2 1" mesh="union_servo_correct_mesh"/>
            <body name="rl_hombro_pierna" pos="0 0 0.002">
              <geom type="mesh" rgba="0.15 0.55 0.78 1" mesh="hombro_pierna_correct_mesh"/>
              <body name="rl_knee_servo" pos="-0.02 0.023 0.02" quat="0.707388 -0.706825 0 0">
                <geom type="mesh" rgba="0.3 0.33 0.38 1" mesh="servo_sin_cabezal_mesh"/>
                <body name="rl_servo_u_2" pos="0 0 0.005" quat="0.707388 0 0 0.706825">
                  <joint name="rl_knee_joint" pos="0 0 0" axis="0 0 1" range="0 1.5708" armature="0.004" damping="0.12" frictionloss="0.003"/>
                  <geom type="mesh" rgba="0.86 0.24 0.24 1" mesh="cad_servo20kg_p4_correct_mesh"/>
                  <body name="rl_pieza1_pierna" pos="-0.02 -0.044 0.001" quat="0.374814 0 0 -0.9271">
                    <joint name="rl_pieza1_pierna_joint" pos="-0.028 0 0" axis="0 0 1" range="-1.5708 1.5708" damping="0.03" frictionloss="0.0002"/>
                    <geom type="mesh" rgba="0.96 0.82 0.18 1" mesh="pieza1_pierna_left_correct_mesh"/>
                  </body>
                </body>
              </body>
              <body name="rl_hip_servo" pos="0 0.023 0.04" quat="9.38559e-07 -9.37812e-07 0.706825 0.707388">
                <geom type="mesh" rgba="0.44 0.29 0.58 1" mesh="servo_sin_cabezal_mesh"/>
                <body name="rl_homoplato" quat="0.923879 0 0 0.382684">
                  <joint name="rl_shoulder_passive_joint" pos="0 0 0" axis="0 0 1" range="-1.5708 1.5708" damping="0.03" frictionloss="0.0002"/>
                  <geom type="mesh" rgba="0.16 0.72 0.45 1" mesh="pieza2_pierna_left_correct_mesh"/>
                  <body name="rl_tensor_aluminio" pos="0.0213 0.0211 0.0067" quat="0.707388 0 0 -0.706825">
                    <joint name="rl_tensor_aluminio_passive_joint" pos="0 0 0" axis="0 0 1" range="-1.5708 1.5708" damping="0.03" frictionloss="0.0002"/>
                    <geom type="mesh" rgba="0.7 0.72 0.7 1" mesh="tensor_aluminio_11_60_correct_mesh"/>
                  </body>
                </body>
                <body name="rl_femur" pos="0 0 0.006" quat="0.923879 0 0 0.382684">
                  <joint name="rl_femur_joint" pos="0 0 0" axis="0 0 1" range="-1.5708 1.5708" damping="0.03" frictionloss="0.0002"/>
                  <geom type="mesh" rgba="0.7 0.45 0.7 1" mesh="pieza3_pierna_felt_correct_mesh"/>
                  <body name="rl_tibia" pos="0.11 0 0.0076" quat="0.382681 0 0 -0.923881">
                    <joint name="rl_tibia_passive_joint" pos="0 0 0" axis="0 0 1" range="-1.5708 1.5708" damping="0.03" frictionloss="0.0002"/>
                    <geom type="mesh" rgba="0.24 0.65 0.65 1" mesh="pieza4_pierna_left_correct_mesh"/>
                    <geom pos="0.11 0 0.003" quat="0.707388 0 0 -0.706825" type="mesh" rgba="0.15 0.15 0.15 1" mesh="foot_left_mesh"/>
                  </body>
                </body>
              </body>
            </body>
          </body>
        </body>
      </body>

      <!-- ================= PATA TRASERA DERECHA (RR) ================= -->
      <body name="rr_mount" pos="-0.11 0.075 0">
        <body name="rr_shoulder_servo" quat="0.000563312 -0.707388 0.000562864 -0.706825">
          <geom type="mesh" rgba="0.18 0.21 0.25 1" mesh="servo_sin_cabezal_mesh"/>
          <body name="rr_servo_u_1" pos="0 0 0.005">
            <joint name="rr_shoulder_joint" pos="0 0 0" axis="0 0 1" range="-1.5708 1.5708" armature="0.004" damping="0.12" frictionloss="0.003"/>
            <geom type="mesh" rgba="0.94 0.55 0.2 1" mesh="union_servo_correct_mesh"/>
            
            <body name="rr_hombro_pierna" pos="0 0 0.002" euler="0 3.14159 3.14159">
              <geom type="mesh" rgba="0.15 0.55 0.78 1" mesh="hombro_pierna_right_mesh"/>
              
              <body name="rr_knee_servo" pos="-0.0200215 0.0230215 -0.0200215" euler="-1.571 0 3.14159">
                <geom type="mesh" rgba="0.3 0.33 0.38 1" mesh="servo_sin_cabezal_mesh"/>
                <body name="rr_servo_u_2" pos="0 0 0.005" euler="0 0 4.7">
                  <joint name="rr_knee_joint" pos="0 0 0" axis="0 0 1" range="-1.57 0" armature="0.004" damping="0.12" frictionloss="0.003"/>
                  <geom type="mesh" rgba="0.86 0.24 0.24 1" mesh="cad_servo20kg_p4_correct_mesh"/>
                  
                  <body name="rr_pieza1_pierna" pos="0.00 -0.02451 0.0093" euler="0 0 2.39">
                    <joint name="rr_pieza1_pierna_joint" pos="0 0 0" axis="0 0 1" range="-1.5708 1.5708" damping="0.03" frictionloss="0.0002"/>
                    <geom type="mesh" rgba="0.96 0.82 0.18 1" mesh="pieza1_pierna_right_mesh"/> 
                  </body>
                </body>
              </body>

              <body name="rr_hip_servo" pos="0 0.0230215 -0.04055" euler="-1.571 0 0">
                <geom type="mesh" rgba="0.44 0.29 0.58 1" mesh="servo_sin_cabezal_mesh"/>
                
                <body name="rr_homoplato" pos="0 0 0" euler="3.14159 0 -2.328">
                  <joint name="rr_shoulder_passive_joint" pos="0 0 0" axis="0 0 1" range="-1.5708 1.5708" damping="0.03" frictionloss="0.0002"/>
                  <geom type="mesh" rgba="0.16 0.72 0.45 1" mesh="pieza2_pierna_right_mesh"/> 
                  
                  <body name="rr_tensor_aluminio" pos="0.02125 0.02108 -0.006" euler=" 0 0 -1.4">
                    <joint name="rr_tensor_aluminio_passive_joint" pos="0 0 0" axis="0 0 1" range="-1.5708 1.5708" damping="0.03" frictionloss="0.0002"/>
                    <geom type="mesh" rgba="0.7 0.72 0.7 1" mesh="tensor_aluminio_11_60_correct_mesh"/>
                  </body>
                </body>

                <body name="rr_femur" pos="0 0 0.006" euler="3.14159 0 4.1">
                  <joint name="rr_femur_joint" pos="0 0 0" axis="0 0 1" range="-1.5708 1.5708" damping="0.03" frictionloss="0.0002"/>
                  <geom type="mesh" rgba="0.7 0.45 0.7 1" mesh="pieza3_pierna_right_mesh"/> 
                  
                  <body name="rr_tibia" pos="0.11 0 -0.0077" euler="0 0 -2.425">
                    <joint name="rr_tibia_passive_joint" pos="0 0 0" axis="0 0 1" range="-1.5708 1.5708" damping="0.03" frictionloss="0.0002"/>
                    <geom type="mesh" rgba="0.24 0.65 0.65 1" mesh="pieza4_pierna_right_mesh"/> 
                    
                    <geom type="mesh" rgba="0.15 0.15 0.15 1" mesh="foot_right_mesh" pos="0.11 0 -0.003" euler="0 0 -1.571"/>
                  </body>
                </body>
              </body>
            </body>
          </body>
        </body>
      </body>
    </body>
  </worldbody>

  <!-- ================= CONTACTOS Y EXCLUSIONES ================= -->
  <contact>
    <!-- Base con los mounts -->
    <exclude body1="base" body2="fl_mount"/>
    <exclude body1="base" body2="rl_mount"/>
    <exclude body1="base" body2="fr_mount"/>
    <exclude body1="base" body2="rr_mount"/>

    <!-- Pata FL -->
    <exclude body1="fl_shoulder_servo" body2="fl_servo_u_1"/>
    <exclude body1="fl_pieza1_pierna" body2="fl_homoplato"/>
    <exclude body1="fl_pieza1_pierna" body2="fl_femur"/>
    <exclude body1="fl_homoplato" body2="fl_femur"/>

    <!-- Pata FR -->
    <exclude body1="fr_shoulder_servo" body2="fr_servo_u_1"/>
    <exclude body1="fr_pieza1_pierna" body2="fr_homoplato"/>
    <exclude body1="fr_pieza1_pierna" body2="fr_femur"/>
    <exclude body1="fr_homoplato" body2="fr_femur"/>

    <!-- Pata RL -->
    <exclude body1="rl_shoulder_servo" body2="rl_servo_u_1"/>
    <exclude body1="rl_pieza1_pierna" body2="rl_homoplato"/>
    <exclude body1="rl_pieza1_pierna" body2="rl_femur"/>
    <exclude body1="rl_homoplato" body2="rl_femur"/>

    <!-- Pata RR -->
    <exclude body1="rr_shoulder_servo" body2="rr_servo_u_1"/>
    <exclude body1="rr_pieza1_pierna" body2="rr_homoplato"/>
    <exclude body1="rr_pieza1_pierna" body2="rr_femur"/>
    <exclude body1="rr_homoplato" body2="rr_femur"/>
  </contact>

  <!-- ================= CINEMÁTICA CERRADA ================= -->
  <equality>
    <!-- Pata FL -->
    <connect body1="fl_pieza1_pierna" body2="fl_homoplato" anchor="0 0 0" solref="0.003" solimp="0.97 0.995 0.0001"/>
    <connect body1="fl_tibia" body2="fl_tensor_aluminio" anchor="-0.03 0 0" solref="0.003" solimp="0.97 0.995 0.0001"/>

    <!-- Pata FR -->
    <connect body1="fr_pieza1_pierna" body2="fr_homoplato" anchor="-0.028 0 0" solref="0.003" solimp="0.97 0.995 0.0001"/>
    <connect body1="fr_tibia" body2="fr_tensor_aluminio" anchor="-0.03 0 0" solref="0.003" solimp="0.97 0.995 0.0001"/>

    <!-- Pata RL -->
    <connect body1="rl_pieza1_pierna" body2="rl_homoplato" anchor="0 0 0" solref="0.003" solimp="0.97 0.995 0.0001"/>
    <connect body1="rl_tibia" body2="rl_tensor_aluminio" anchor="-0.03 0 0" solref="0.003" solimp="0.97 0.995 0.0001"/>

    <!-- Pata RR -->
    <connect body1="rr_pieza1_pierna" body2="rr_homoplato" anchor="-0.028 0 0" solref="0.003" solimp="0.97 0.995 0.0001"/>
    <connect body1="rr_tibia" body2="rr_tensor_aluminio" anchor="-0.03 0 0" solref="0.003" solimp="0.97 0.995 0.0001"/>
  </equality>

  <!-- ================= MOTORES ================= -->
  <actuator>
    <!-- Pata FL -->
    <general joint="fl_shoulder_joint" ctrlrange="-1.57 1.57" forcerange="-8 8" dyntype="filterexact" dynprm="0.02 0 0 0 0 0 0 0 0 0" biastype="affine" gainprm="18" biasprm="0 -18"/>
    <general joint="fl_knee_joint" ctrlrange="0 1.57" forcerange="-8 8" dyntype="filterexact" dynprm="0.02 0 0 0 0 0 0 0 0 0" biastype="affine" gainprm="18" biasprm="0 -18"/>
    <general joint="fl_femur_joint" ctrlrange="-1.57 1.57" forcerange="-8 8" dyntype="filterexact" dynprm="0.02 0 0 0 0 0 0 0 0 0" biastype="affine" gainprm="18" biasprm="0 -18"/>

    <!-- Pata FR -->
    <general joint="fr_shoulder_joint" ctrlrange="-1.57 1.57" forcerange="-8 8" dyntype="filterexact" dynprm="0.02 0 0 0 0 0 0 0 0 0" biastype="affine" gainprm="18" biasprm="0 -18"/>
    <general joint="fr_knee_joint" ctrlrange="-1.57 0" forcerange="-8 8" dyntype="filterexact" dynprm="0.02 0 0 0 0 0 0 0 0 0" biastype="affine" gainprm="18" biasprm="0 -18"/>
    <general joint="fr_femur_joint" ctrlrange="-1.57 1.57" forcerange="-8 8" dyntype="filterexact" dynprm="0.02 0 0 0 0 0 0 0 0 0" biastype="affine" gainprm="18" biasprm="0 -18"/>

    <!-- Pata RL -->
    <general joint="rl_shoulder_joint" ctrlrange="-1.57 1.57" forcerange="-8 8" dyntype="filterexact" dynprm="0.02 0 0 0 0 0 0 0 0 0" biastype="affine" gainprm="18" biasprm="0 -18"/>
    <general joint="rl_knee_joint" ctrlrange="0 1.57" forcerange="-8 8" dyntype="filterexact" dynprm="0.02 0 0 0 0 0 0 0 0 0" biastype="affine" gainprm="18" biasprm="0 -18"/>
    <general joint="rl_femur_joint" ctrlrange="-1.57 1.57" forcerange="-8 8" dyntype="filterexact" dynprm="0.02 0 0 0 0 0 0 0 0 0" biastype="affine" gainprm="18" biasprm="0 -18"/>

    <!-- Pata RR -->
    <general joint="rr_shoulder_joint" ctrlrange="-1.57 1.57" forcerange="-8 8" dyntype="filterexact" dynprm="0.02 0 0 0 0 0 0 0 0 0" biastype="affine" gainprm="18" biasprm="0 -18"/>
    <general joint="rr_knee_joint" ctrlrange="-1.57 0" forcerange="-8 8" dyntype="filterexact" dynprm="0.02 0 0 0 0 0 0 0 0 0" biastype="affine" gainprm="18" biasprm="0 -18"/>
    <general joint="rr_femur_joint" ctrlrange="-1.57 1.57" forcerange="-8 8" dyntype="filterexact" dynprm="0.02 0 0 0 0 0 0 0 0 0" biastype="affine" gainprm="18" biasprm="0 -18"/>
  </actuator>
</mujoco>
