<mujoco model="serial_leg">
  <compiler angle="radian" meshdir="assets/"/>

  <option timestep="0.001" integrator="implicitfast" iterations="80" ls_iterations="30"/>

  <visual>
    <global offwidth="1692" offheight="936"/>
    <headlight ambient="0.45 0.45 0.45" diffuse="0.75 0.75 0.75" specular="0.15 0.15 0.15"/>
  </visual>

  <statistic meaninertia="0.00126322" extent="0.238549" center="0.0567529 -0.0356881 0.943493"/>

  <asset>
    <mesh name="cad_servo20kg_p4_correct_mesh" file="cad_servo20kg_p4_correct.stl" scale="0.001 0.001 0.001"/>
    <mesh name="foot_left_mesh" file="foot_left.stl" scale="0.001 0.001 0.001"/>
    <mesh name="hombro_pierna_correct_mesh" file="hombro_pierna_correct.stl" scale="0.001 0.001 0.001"/>
    <mesh name="pieza1_pierna_left_correct_mesh" file="pieza1_pierna_left_correct_mk2.stl" scale="0.001 0.001 0.001"/>
    <mesh name="pieza2_pierna_left_correct_mesh" file="pieza2_pierna_left_correct.stl" scale="0.001 0.001 0.001"/>
    <mesh name="pieza3_pierna_felt_correct_mesh" file="pieza3_pierna_felt_correct.stl" scale="0.001 0.001 0.001"/>
    <mesh name="pieza4_pierna_left_correct_mesh" file="pieza4_pierna_right_correct.stl" scale="0.001 0.001 0.001"/>
    <mesh name="servo_sin_cabezal_mesh" file="servo_sin_cabezal.stl" scale="0.001 0.001 0.001"/>
    <mesh name="tensor_aluminio_11_60_correct_mesh" file="tensor_aluminio_11_60_correct.stl" scale="0.001 0.001 0.001"/>
    <mesh name="union_servo_correct_mesh" file="union_servo_correct.stl" scale="0.001 0.001 0.001"/>
  </asset>

  <worldbody>
    <light pos="0 0 3" dir="0 0 -1"/>
    <body name="shoulder_servo" pos="0 0 1" quat="0.000563312 0.707388 0.000562864 0.706825">
      <geom type="mesh" rgba="0.18 0.21 0.25 1" mesh="servo_sin_cabezal_mesh"/>
      <body name="servo_u_1" pos="0 0 0.005">
        <joint name="shoulder_joint" pos="0 0 0" axis="0 0 1" range="-1.5708 1.5708" armature="0.004" damping="0.12" frictionloss="0.003"/>
        <geom type="mesh" rgba="0.94 0.55 0.2 1" mesh="union_servo_correct_mesh"/>
        <body name="hombro_pierna" pos="0 0 0.002">
          <geom type="mesh" rgba="0.15 0.55 0.78 1" mesh="hombro_pierna_correct_mesh"/>
          <body name="knee_servo" pos="-0.02 0.023 0.02" quat="0.707388 -0.706825 0 0">
            <geom type="mesh" rgba="0.3 0.33 0.38 1" mesh="servo_sin_cabezal_mesh"/>
            <body name="servo_u_2" pos="0 0 0.005" euler="0 0 -4.0">
              <joint name="knee_joint" pos="0 0 0" axis="0 0 1" range="-0.87 0.7" armature="0.004" damping="0.12" frictionloss="0.003"/>
              <geom type="mesh" rgba="0.86 0.24 0.24 1" mesh="cad_servo20kg_p4_correct_mesh"/>
              <body name="pieza1_pierna" pos="-0.028 -0.026 0.001" euler="0 0 3.2"> <!-- amarillo quat="0.374814 0 0 -0.9271" pos="-0.02 -0.044 0.001"-->
                <joint name="pieza1_pierna_joint" pos="-0.028 0 0" axis="0 0 1" range="-1.5708 1.5708" damping="0.03" frictionloss="0.0002"/>
                <geom type="mesh" rgba="0.96 0.82 0.18 1" mesh="pieza1_pierna_left_correct_mesh"/>
              </body>
            </body>
          </body>
          <body name="hip_servo" pos="0 0.023 0.04" quat="9.38559e-07 -9.37812e-07 0.706825 0.707388">
            <geom type="mesh" rgba="0.44 0.29 0.58 1" mesh="servo_sin_cabezal_mesh"/>
            <body name="homoplato" euler="0 0 1.5">
              <joint name="shoulder_passive_joint" pos="0 0 0" axis="0 0 1" range="-1.5708 1.5708" damping="0.03" frictionloss="0.0002"/>
              <geom type="mesh" rgba="0.16 0.72 0.45 1" mesh="pieza2_pierna_left_correct_mesh"/>
              <body name="tensor_aluminio" pos="0.0213 0.0211 0.0067" euler="0 0 -1.48">
                <joint name="tensor_aluminio_passive_joint" pos="0 0 0" axis="0 0 1" range="-1.5708 1.5708" damping="0.03" frictionloss="0.0002"/>
                <geom type="mesh" rgba="0.7 0.72 0.7 1" mesh="tensor_aluminio_11_60_correct_mesh"/>
              </body>
            </body>
            <body name="femur" pos="0 0 0.006" euler="0 0 1.5708"> <!-- lila femur -->
              <joint name="femur_joint" pos="0 0 0" axis="0 0 1" range="-1.5708 1.5708" damping="0.03" frictionloss="0.0002"/>
              <geom type="mesh" rgba="0.7 0.45 0.7 1" mesh="pieza3_pierna_felt_correct_mesh"/>
              <body name="tibia" pos="0.11 0 0.0076" euler="3.14159 0 2.3562">
                <joint name="tibia_passive_joint" pos="0 0 0" axis="0 0 1" range="-1.5708 1.5708" damping="0.03" frictionloss="0.0002"/>
                <geom type="mesh" rgba="0.24 0.65 0.65 1" mesh="pieza4_pierna_left_correct_mesh"/>
                <geom type="mesh" rgba="0.15 0.15 0.15 1" mesh="foot_left_mesh" pos="0.11 0 -0.003" euler="0 0 -1.57"/>
              </body>
            </body>
          </body>
        </body>
      </body>
    </body>
  </worldbody>

  <contact>
    <exclude body1="shoulder_servo" body2="servo_u_1"/>
    <exclude body1="homoplato" body2="femur"/>
    <exclude body1="homoplato" body2="pieza1_pierna"/>
    <exclude body1="femur" body2="pieza1_pierna"/>
  </contact>

  <equality>
    <connect body1="pieza1_pierna" body2="homoplato" anchor="0 0 0" solref="0.003" solimp="0.97 0.995 0.0001"/>
    <connect body1="tibia" body2="tensor_aluminio" anchor="-0.03 0 0" solref="0.003" solimp="0.97 0.995 0.0001"/>
  </equality>

  <actuator>
    <general joint="shoulder_joint" ctrlrange="-1.57 1.57" forcerange="-8 8" dyntype="filterexact" dynprm="0.02 0 0 0 0 0 0 0 0 0" biastype="affine" gainprm="18" biasprm="0 -18"/>
    <general joint="knee_joint" ctrlrange="-0.87 0.7" forcerange="-8 8" dyntype="filterexact" dynprm="0.02 0 0 0 0 0 0 0 0 0" biastype="affine" gainprm="18" biasprm="0 -18"/>
    <general joint="femur_joint" ctrlrange="-1.57 1.57" forcerange="-8 8" dyntype="filterexact" dynprm="0.02 0 0 0 0 0 0 0 0 0" biastype="affine" gainprm="18" biasprm="0 -18"/>
  </actuator>

  <keyframe>
    <key
      time="835.929"
      qpos="-0.7023 -0.610055 0.613813 -0.618888 -0.809192 -1.4134 -0.770019"
      qvel="5.12982e-14 5.48524e-14 2.01825e-14 5.34931e-14 -1.28641e-14 -4.20449e-14 2.28102e-14"
      act="-0.7065 -0.61095 -1.413"
      ctrl="-0.7065 -0.61095 -1.413"
    />
  </keyframe>
</mujoco>
